Workbook

Sheet Dashboard
A1: TIA Enterprise - delivery dashboard
A2: Formulas over the other sheets. Edit blue cells on Task Tracker / Requirements / Acceptance Criteria.
A3: Last updated | B3: 46325
A5: Tasks | D5: Requirements (FR / PL / NFR) | G5: Acceptance criteria
A6: Total tasks | B6: =COUNTA('Task Tracker'!$A$2:$A$251) -> 100 | D6: Total | E6: =COUNTA(Requirements!$A$2:$A$120) -> 69 | G6: Total | H6: =COUNTA('Acceptance Criteria'!$A$2:$A$72) -> 41
A7: Completed | B7: =COUNTIF('Task Tracker'!$I$2:$I$251,"Completed") -> 50 | D7: Done | E7: =COUNTIF(Requirements!$D$2:$D$120,"Done") -> 14 | G7: Done | H7: =COUNTIF('Acceptance Criteria'!$D$2:$D$72,"Done") -> 23
A8: In progress | B8: =COUNTIF('Task Tracker'!$I$2:$I$251,"In Progress") -> 0 | D8: Partial | E8: =COUNTIF(Requirements!$D$2:$D$120,"Partial") -> 19 | G8: Partial | H8: =COUNTIF('Acceptance Criteria'!$D$2:$D$72,"Partial") -> 2
A9: Not started | B9: =COUNTIF('Task Tracker'!$I$2:$I$251,"Not Started") -> 50 | D9: Not started | E9: =COUNTIF(Requirements!$D$2:$D$120,"Not started") -> 36 | G9: Not started | H9: =COUNTIF('Acceptance Criteria'!$D$2:$D$72,"Not started") -> 16
A10: Blocked | B10: =COUNTIF('Task Tracker'!$I$2:$I$251,"Blocked") -> 0 | D10: % done | E10: =IFERROR(E7/E6,0) -> 0.20289855 | G10: % done | H10: =IFERROR(H7/H6,0) -> 0.56097561
A11: % tasks completed | B11: =IFERROR(B7/B6,0) -> 0.5
A12: Consistency: Completed rows not at 100% | B12: =SUMPRODUCT(('Task Tracker'!$I$2:$I$251="Completed")*('Task Tracker'!$J$2:$J$251<>1)) -> 0
A14: By release
A15: Release | B15: Tasks | C15: Completed | D15: In progress | E15: Not started | F15: % tasks done | G15: ACs done | H15: ACs total
A16: 0 Specification | B16: =COUNTIF('Task Tracker'!$B$2:$B$251,$A16) -> 6 | C16: =COUNTIFS('Task Tracker'!$B$2:$B$251,$A16,'Task Tracker'!$I$2:$I$251,"Completed") -> 6 | D16: =COUNTIFS('Task Tracker'!$B$2:$B$251,$A16,'Task Tracker'!$I$2:$I$251,"In Progress") -> 0 | E16: =COUNTIFS('Task Tracker'!$B$2:$B$251,$A16,'Task Tracker'!$I$2:$I$251,"Not Started") -> 0 | F16: =IFERROR(C16/B16,0) -> 1 | G16: 0 | H16: 0
A17: R1 Platform foundation & cross-repo impact | B17: =COUNTIF('Task Tracker'!$B$2:$B$251,$A17) -> 48 | C17: =COUNTIFS('Task Tracker'!$B$2:$B$251,$A17,'Task Tracker'!$I$2:$I$251,"Completed") -> 44 | D17: =COUNTIFS('Task Tracker'!$B$2:$B$251,$A17,'Task Tracker'!$I$2:$I$251,"In Progress") -> 0 | E17: =COUNTIFS('Task Tracker'!$B$2:$B$251,$A17,'Task Tracker'!$I$2:$I$251,"Not Started") -> 4 | F17: =IFERROR(C17/B17,0) -> 0.91666667 | G17: =COUNTIFS('Acceptance Criteria'!$C$2:$C$72,1,'Acceptance Criteria'!$D$2:$D$72,"Done") -> 23 | H17: =COUNTIF('Acceptance Criteria'!$C$2:$C$72,1) -> 25
A18: R2 Enterprise evidence & governance | B18: =COUNTIF('Task Tracker'!$B$2:$B$251,$A18) -> 22 | C18: =COUNTIFS('Task Tracker'!$B$2:$B$251,$A18,'Task Tracker'!$I$2:$I$251,"Completed") -> 0 | D18: =COUNTIFS('Task Tracker'!$B$2:$B$251,$A18,'Task Tracker'!$I$2:$I$251,"In Progress") -> 0 | E18: =COUNTIFS('Task Tracker'!$B$2:$B$251,$A18,'Task Tracker'!$I$2:$I$251,"Not Started") -> 22 | F18: =IFERROR(C18/B18,0) -> 0 | G18: =COUNTIFS('Acceptance Criteria'!$C$2:$C$72,2,'Acceptance Criteria'!$D$2:$D$72,"Done") -> 0 | H18: =COUNTIF('Acceptance Criteria'!$C$2:$C$72,2) -> 11
A19: R3 Operational intelligence & scale | B19: =COUNTIF('Task Tracker'!$B$2:$B$251,$A19) -> 10 | C19: =COUNTIFS('Task Tracker'!$B$2:$B$251,$A19,'Task Tracker'!$I$2:$I$251,"Completed") -> 0 | D19: =COUNTIFS('Task Tracker'!$B$2:$B$251,$A19,'Task Tracker'!$I$2:$I$251,"In Progress") -> 0 | E19: =COUNTIFS('Task Tracker'!$B$2:$B$251,$A19,'Task Tracker'!$I$2:$I$251,"Not Started") -> 10 | F19: =IFERROR(C19/B19,0) -> 0 | G19: =COUNTIFS('Acceptance Criteria'!$C$2:$C$72,3,'Acceptance Criteria'!$D$2:$D$72,"Done") -> 0 | H19: =COUNTIF('Acceptance Criteria'!$C$2:$C$72,3) -> 2
A20: R4 Extended coverage & advanced (GA) | B20: =COUNTIF('Task Tracker'!$B$2:$B$251,$A20) -> 14 | C20: =COUNTIFS('Task Tracker'!$B$2:$B$251,$A20,'Task Tracker'!$I$2:$I$251,"Completed") -> 0 | D20: =COUNTIFS('Task Tracker'!$B$2:$B$251,$A20,'Task Tracker'!$I$2:$I$251,"In Progress") -> 0 | E20: =COUNTIFS('Task Tracker'!$B$2:$B$251,$A20,'Task Tracker'!$I$2:$I$251,"Not Started") -> 14 | F20: =IFERROR(C20/B20,0) -> 0 | G20: =COUNTIFS('Acceptance Criteria'!$C$2:$C$72,4,'Acceptance Criteria'!$D$2:$D$72,"Done") -> 0 | H20: =COUNTIF('Acceptance Criteria'!$C$2:$C$72,4) -> 3
A21: Total | B21: =SUM(B16:B20) -> 100 | C21: =SUM(C16:C20) -> 50 | D21: =SUM(D16:D20) -> 0 | E21: =SUM(E16:E20) -> 50 | F21: =IFERROR(C21/B21,0) -> 0.5 | G21: =SUM(G16:G20) -> 23 | H21: =SUM(H16:H20) -> 41
A23: GA readiness (all requirements Done and all acceptance criteria Done) | B23: =IF(AND(E7=E6,H7=H6),"READY","NOT READY") -> NOT READY

Sheet Task Tracker
A1: ID | B1: Release | C1: Workstream | D1: Task | E1: Details / acceptance | F1: Requirement refs | G1: Output / location | H1: Priority | I1: Status | J1: % Complete | K1: Effort (rough) | L1: Depends on | M1: Next order | N1: Completed on | O1: Verified by | P1: Notes
A2: T-001 | B2: 0 Specification | C2: Specification | D2: Review PRD v2.0 and companion documents | E2: Critique; cross-document contradictions. | F2: - | G2: chat review | H2: P0 | I2: Completed | J2: 1 | K2: M | N2: 46323 | O2: Docs rendered and reviewed
A3: T-002 | B3: 0 Specification | C3: Specification | D3: Rewrite PRD v2.1, ARCHITECTURE v1.1, TFD v1.1 | E3: Resolution strategies, severity model, canonical model, corrected diagrams. | F3: - | G3: revised/*.md, *.pdf | H3: P0 | I3: Completed | J3: 1 | K3: M | N3: 46323 | O3: Docs rendered and reviewed
A4: T-003 | B4: 0 Specification | C4: Specification | D4: Re-plan as enterprise product: PRD v3.0, ARCH/TFD v1.2 | E4: Removed MVP/pilot; Releases 1-4; all requirements mandatory; FR-039..045, PL-001..012, AC-021..038. | F4: - | G4: revised/*.md, *.pdf | H4: P0 | I4: Completed | J4: 1 | K4: M | N4: 46324 | O4: Docs rendered and reviewed
A5: T-004 | B5: 0 Specification | C5: Specification | D5: SaaS multi-tenant model: PRD v3.1, ARCH/TFD v1.3 | E5: Shared schema + RLS, dedicated option, PL-013..018, AC-039..041. | F5: - | G5: revised/*.md, *.pdf | H5: P0 | I5: Completed | J5: 1 | K5: M | N5: 46324 | O5: Docs rendered and reviewed
A6: T-005 | B6: 0 Specification | C6: Specification | D6: Resume file summary.md | E6: Narrative log for session recovery. | F6: - | G6: summary.md | H6: P0 | I6: Completed | J6: 1 | K6: M | N6: 46323 | O6: Docs rendered and reviewed
A7: T-006 | B7: 0 Specification | C7: Specification | D7: Project tracker workbook | E7: This file; requirement traceability. | F7: - | G7: TIA-Project-Tracker.xlsx | H7: P0 | I7: Completed | J7: 1 | K7: M | N7: 46324 | O7: Docs rendered and reviewed
A8: T-007 | B8: R1 Platform foundation & cross-repo impact | C8: Engine | D8: Canonical data model, statuses, path normalisation | E8: Entities, evidence/analysis statuses. | F8: FR-008 FR-010 | G8: tia/models.py | H8: P0 | I8: Completed | J8: 1 | K8: M | N8: 46323 | O8: test_normalize_path
A9: T-008 | B9: R1 Platform foundation & cross-repo impact | C9: Engine | D9: Read-only git access | E9: Revisions, trees, diffs; never executes repo code. | F9: FR-002 | G9: tia/gitutil.py | H9: P0 | I9: Completed | J9: 1 | K9: M | N9: 46323 | O9: acceptance tests | P9: Local clones only until GitHub App connector
A10: T-009 | B10: R1 Platform foundation & cross-repo impact | C10: Extraction | D10: Python adapter: endpoints, schemas, functions, outbound calls, tests | E10: FastAPI/Flask, pydantic, requests/httpx, generated clients. | F10: FR-004 FR-012 FR-017 | G10: tia/extract_python.py | H10: P0 | I10: Completed | J10: 1 | K10: M | N10: 46323 | O10: test_units.py, AC-002/004
A11: T-010 | B11: R1 Platform foundation & cross-repo impact | C11: Resolution | D11: Cross-repo resolution R1, R2, R3, R5 + corroboration | E11: Service map (R4) input; never by name alone. | F11: FR-014 | G11: tia/resolve.py | H11: P0 | I11: Completed | J11: 1 | K11: M | N11: 46323 | O11: AC-004/018/019 tests
A12: T-011 | B12: R1 Platform foundation & cross-repo impact | C12: Engine | D12: Typed graph, test association | E12: Impact-direction index; import/HTTP/naming association. | F12: FR-013 FR-021 | G12: tia/graph.py | H12: P0 | I12: Completed | J12: 1 | K12: M | N12: 46323 | O12: AC-003/006 tests
A13: T-012 | B13: R1 Platform foundation & cross-repo impact | C13: Engine | D13: Basic REST contract diff | E13: P0 list; others 'not evaluated'. | F13: FR-018 | G13: tia/contracts.py | H13: P0 | I13: Completed | J13: 1 | K13: M | N13: 46323 | O13: test_removed_endpoint_is_breaking
A14: T-013 | B14: R1 Platform foundation & cross-repo impact | C14: Engine | D14: Severity and materiality rules | E14: Change nature x criticality; inferred cap. | F14: PRD-7.3 | G14: tia/severity.py | H14: P0 | I14: Completed | J14: 1 | K14: M | N14: 46323 | O14: test_severity_*
A15: T-014 | B15: R1 Platform foundation & cross-repo impact | C15: Engine | D15: Impact engine: bounded traversal, unknowns, status | E15: Two-pass BFS, limits, coverage, status semantics. | F15: FR-013 FR-015 FR-016 | G15: tia/impact.py | H15: P0 | I15: Completed | J15: 1 | K15: M | N15: 46323 | O15: AC-009/010/012 tests
A16: T-015 | B16: R1 Platform foundation & cross-repo impact | C16: Reporting | D16: JSON report, PR comment renderer, audience redaction | E16: Single-marker advisory comment; no leaks. | F16: FR-035 PL-002 | G16: tia/report.py | H16: P0 | I16: Completed | J16: 1 | K16: M | N16: 46323 | O16: AC-016/020 tests
A17: T-016 | B17: R1 Platform foundation & cross-repo impact | C17: Interfaces | D17: CLI analyze + FastAPI wrapper | E17: Synchronous API; header-based audience placeholder. | F17: PL-008 | G17: tia/cli.py, tia/api.py | H17: P0 | I17: Completed | J17: 1 | K17: M | N17: 46323 | O17: test_api.py
A18: T-017 | B18: R1 Platform foundation & cross-repo impact | C18: Connectors | D18: Repository ingestion service: GitHub, Azure DevOps, any git URL, file:// URL, local path | E18: Clone/sync via git; PAT via env only; PR ref fetch by number; merge-base; friendly errors; host allow-list; local paths gated. | F18: FR-001 FR-039(partial) | G18: tia/repos.py | H18: P0 | I18: Completed | J18: 1 | K18: M | N18: 46323 | O18: tests/test_ingest.py (real git repos; real GitHub clone checked manually) | P18: Token auth for private repos untested against real ADO/GitHub (no credentials here)
A19: T-018 | B19: R1 Platform foundation & cross-repo impact | C19: Connectors | D19: Bulk discovery: whole ADO project / GitHub org or user | E19: REST listing + ingest all; supports on-prem ADO / GHE api_base. | F19: FR-001 | G19: tia/repos.py | H19: P0 | I19: Completed | J19: 1 | K19: M | N19: 46323 | O19: test_discover_ado_and_github (fake API servers only) | P19: Needs real PAT to verify
A20: T-019 | B20: R1 Platform foundation & cross-repo impact | C20: Interfaces | D20: Web UI v0 + server entry point | E20: Ingest (URL / discovery / path), repo list with sync/remove, analysis (branch or PR), report, unknowns, PR-comment markdown. | F20: PRD-9 (partial) | G20: tia/web/index.html, tia/server.py | H20: P0 | I20: Completed | J20: 1 | K20: M | N20: 46323 | O20: manual run + test_api_end_to_end_with_demo_landscape | P20: Dev mode: no auth, no tenancy; not the R2 UI
A21: T-020 | B21: R1 Platform foundation & cross-repo impact | C21: Graph | D21: Code / dependency graph explorer v0 | E21: Services, endpoints+schemas, and function-level views from the persisted extracts; filter by repo, search, focus (neighbourhood), node limit with truncation notice; evidence-coloured edges; unresolved calls shown; node/edge detail panel with file:line evidence. | F21: PRD-9.2 | G21: tia/graphview.py, tia/api.py (/api/v1/graph*), tia/web/index.html, tia/web/vendor/cytoscape (bundled, MIT) | H21: P0 | I21: Completed | J21: 1 | K21: M | N21: 46323 | O21: tests/test_graph.py (8) + headless Chrome run: all 3 levels, search, focus, details, 0 console errors | P21: Graph is rebuilt from cached extracts per request (not a persisted graph store yet)
A22: T-021 | B22: R1 Platform foundation & cross-repo impact | C22: Graph | D22: Impact overlay on the graph | E22: Changed component -> via -> affected, edges by evidence status, nodes coloured by severity, one click from the report. | F22: PRD-9.2 FR-013 | G22: tia/graphview.py (impact_overlay), /api/v1/impact-analyses/{id}/graph | H22: P0 | I22: Completed | J22: 1 | K22: M | N22: 46323 | O22: test_graph_api_and_impact_overlay + headless Chrome run
A23: T-022 | B23: R1 Platform foundation & cross-repo impact | C23: Platform | D23: Multi-tenant PostgreSQL storage: schema, SQL migrations, forced RLS, tenant-bound transactions | E23: tenants registry; tenant_id on every row; FORCE ROW LEVEL SECURITY; runtime role tia_app (not owner, no BYPASSRLS, no access to registry); set_config per transaction; connection pool; migration runner; SQLite removed. | F23: PL-003 AC-035 TFD-9 | G23: tia/db.py, tia/store.py, tia/migrations/0001_init.sql, tia/migrate.py | H23: P0 | I23: Completed | J23: 1 | K23: M | N23: 46323 | O23: tests/test_storage.py (isolation, no-tenant, unfiltered delete, privileges, forced RLS) on real PostgreSQL 16.2; whole suite (69) now runs on PostgreSQL | P23: Embedded PostgreSQL 16.2 only; a managed PG / PgBouncer deployment is untested (set_config is transaction-local so transaction pooling is safe by design). Tenant is fixed per process until SSO (UC1-18/19).
A24: T-023 | B24: R1 Platform foundation & cross-repo impact | C24: Security | D24: Tamper-evident, append-only, keyed (HMAC) audit chain per tenant | E24: Advisory-locked sequential chain; runtime role has INSERT/SELECT only; HMAC key kept outside the DB so an owner cannot recompute the chain; verify endpoint; repository register/sync/PR-fetch/remove audited (no tokens). | F24: 11.3 | G24: tia/store.py (audit, verify_audit), /api/v1/audit, /api/v1/audit/verify | H24: P0 | I24: Completed | J24: 1 | K24: M | N24: 46323 | O24: tests: tamper, delete, reorder, append-only, 48 concurrent writes, keyed-vs-unkeyed owner rewrite, no secrets in audit | P24: Audit of GitHub/ADO comment posting and logins is added with those items
A25: T-024 | B25: R1 Platform foundation & cross-repo impact | C25: Platform | D25: Job queue + worker: idempotent, newest-wins, fair across tenants, exact per-tenant cap, retries with backoff, leases | E25: jobs table under RLS; tia_worker role is the only one that sees all tenants' jobs; enqueue/claim/heartbeat/succeed/fail/reap; worker loop with PermanentError; shared resolve/execute service used by sync API and worker; ?async=true API, job status and cancel endpoints; tokens refused in queued work. | F25: PL-017 AC-040 TFD-8 TFD-12 | G25: tia/jobs.py, tia/worker.py, tia/analysis_service.py, tia/migrations/0002_jobs.sql, /api/v1/jobs | H25: P0 | I25: Completed | J25: 1 | K25: M | N25: 46323 | O25: tests/test_jobs.py (20): idempotency, supersede, cancel, force, role isolation, fairness, cap (also under 12 concurrent claims), retry/backoff/permanent, lease recovery + stale worker, 6 workers x 30 jobs exactly once, API->queue->worker end to end; repeated 4x stable; live run on the dev server | P25: Real PostgreSQL 16.2. Workers share the repo filesystem path with the API (shared volume / object store is a deployment item under UC1-23). Fairness is round-robin by queued position, not weighted by plan.
A26: T-025 | B26: R1 Platform foundation & cross-repo impact | C26: Platform | D26: Persisted versioned graph + per-file incremental extraction + full-rescan path | E26: Per-file facts cached by git blob id; content-addressed immutable graph versions with a head per landscape; head advances on register/sync/delete/webhook; POST /graph/rescan re-derives everything, detects drift against the incremental result and repairs it. | F26: FR-003 AC-021 | G26: tia/extraction.py, tia/graphstore.py, tia/migrations/0003-0004, /api/v1/graph/versions, /api/v1/graph/rescan | H26: P0 | I26: Completed | J26: 1 | K26: M | N26: 46323 | O26: tests/test_incremental.py (7), tests/test_graph_versions.py (9): incremental result and graph equal a full rescan; a one-file push adds exactly one cached file fact end to end; tenant isolation; rescan detects and repairs a corrupted cache | P26: Python adapter only (Java is UC1-07). Real PostgreSQL 16.2 + real git.
A27: T-026 | B27: R1 Platform foundation & cross-repo impact | C27: Platform | D27: Stale-relationship handling + repository freshness (scan state) | E27: Cross-repo relationship history (current | stale: scan_failed, parse_failed, evidence_removed); repos track scan status, last successful scan and analysed revision; reports carry per-repo freshness, a repository_freshness unknown, status partial on a failed scan, and stale-evidence findings capped at Medium; graph view draws stale edges as stale. | F27: FR-005 FR-010 AC-011 AC-022 | G27: tia/relationships.py, tia/repos.py (scan state), tia/impact.py, tia/migrations/0005, /api/v1/graph/relationships | H27: P0 | I27: Completed | J27: 1 | K27: M | N27: 46323 | O27: tests/test_stale.py (6): failed scan -> stale finding + last good scan stated -> recovery; removed call; unparseable consumer file; repository removal; redaction; no needless rewrites | P27: runtime_observed evidence (R6) still never produced. No interim 'pending re-scan' state between a push and the synchronous refresh.
A28: T-027 | B28: R1 Platform foundation & cross-repo impact | C28: Platform | D28: Evidence snapshot materialisation + reproduction | E28: Immutable snapshot per analysis (revisions of every repo incl. target head, extractor/config versions, graph version, freshness and stale-relationship state); commits pinned in TIA clones; POST /impact-analyses/{id}/reproduce re-runs on the snapshot and reports identical or not; evidence view shows the path and revision of each hop of every material finding. | F28: AC-015 | G28: tia/migrations/0006, tia/analysis_service.py (reproduce, pin_analysis), tia/report.py (evidence_view), /api/v1/evidence-snapshots, /impact-analyses/{id}/evidence|reproduce | H28: P0 | I28: Completed | J28: 1 | K28: M | N28: 46323 | O28: tests/test_snapshots.py (8): identical after the landscape moved on; stale state pinned; pins survive history rewrite and gc (and without pins TIA says the evidence is gone); immutable by privilege; tenant isolation; audience redaction | P28: Local repositories are read in place and cannot be pinned (a rewritten local history makes reproduction fail with a clear message).
A29: T-028 | B29: R1 Platform foundation & cross-repo impact | C29: Connectors | D29: Code upload from the user's drive: zip and whole folder, 2 GiB cap | E29: Session-based upload API (zip streamed as one body, folder in batches), safe extraction (traversal/absolute/drive/device names, ADS, symlinks, encrypted, case collisions rejected; caps enforced on bytes written), each upload a git commit so two uploads are analysed like a PR; UI tab with progress; one-call PUT for scripts. | F29: FR-001 | G29: tia/upload.py, tia/api.py (/api/v1/uploads, /repositories/{name}/upload, /revisions), tia/web/index.html | H29: P0 | I29: Completed | J29: 1 | K29: M | N29: 46323 | O29: tests/test_upload.py (33); real Chrome (zip + folder + analyse vs previous upload, 0 console errors); live 721 MB zip streamed with 2 MB server memory growth; declared 3 GB refused with 413 | P29: Per-upload cap only: no per-tenant total storage quota yet (UC1-20/21). Uploaded code is parsed, never executed. Uploads are snapshots (files absent from a re-upload are removed).
A30: T-029 | B30: R1 Platform foundation & cross-repo impact | C30: Extraction | D30: Java / Spring adapter (REST): routes, DTO schemas, RestTemplate/WebClient/RestClient/OpenFeign/shared clients, JUnit + MockMvc tests | E30: tree-sitter-java parser; Spring Web endpoints (class prefix, arrays, RequestMethod lists, controller interfaces), request/response schemas incl. wrappers, records, entities, inheritance and Jackson naming; base URLs from constants, @Value, environment, WebClient/RestTemplate builders; Feign and shared-client calls resolved at assembly (R2/R1); spring.application.name as default service identity; unsupported HTTP client libraries disclosed as an unknown; per-file incremental caching preserved. | F30: FR-004 FR-012 FR-017 AC-023 | G30: tia/extract_java.py, tia/extract_python.py (assembly), tia/extraction.py | H30: P0 | I30: Completed | J30: 1 | K30: M | N30: 46323 | O30: tests/test_java.py (35): facts, cross-language Python<->Java and Java<->Java resolution, impact on real branches, parse failures, incremental == full rescan; run on real third-party code (spring-petclinic-microservices: 54 files, 0 parse failures, 16 endpoints, the 2 real service-to-service calls resolved source_confirmed) | P30: Spring MVC/WebFlux/OpenFeign only (no JAX-RS, Micronaut, Quarkus, Spring Cloud Gateway routes); OkHttp/Apache/java.net.http/Retrofit calls are reported as unknown, not analysed; @RequestMapping without a method is read as GET; dynamic base URLs stay unresolved; variable types are resolved per file by name; endpoint auth config (FR-017) not extracted; no accuracy measurement yet (UC1-25).
A31: T-030 | B31: R1 Platform foundation & cross-repo impact | C31: Extraction | D31: Python ORM + migration extraction: SQLAlchemy (declarative, Mapped, Flask-SQLAlchemy), SQLModel, Django models; Alembic and Django migrations | E31: Entities -> tables -> columns (nullability, keys, FK and many-to-many link tables, inherited mixins and Django auth bases); model references inside functions classified read/write (objects.*, session.query/add/delete, select/insert/update/delete, save(), self/cls); Alembic upgrade() ops incl. batch_alter_table and op.execute SQL; Django CreateModel/AddField/RemoveField/AlterField/RenameField/DeleteModel/RenameModel/AlterModelTable/RunSQL; raw SQL, Table() objects, dynamic table names, RunPython and unknown bases reported as data access not analysed. | F31: FR-006 FR-006a | G31: tia/extract_orm.py, tia/extract_data.py, tia/extract_python.py | H31: P0 | I31: Completed | J31: 1 | K31: M | N31: 46323 | O31: tests/test_data.py (58 incl. Python models, references, Alembic, Django); run on real third-party code: django-realworld-example-app (5 models, 5 link tables) and fastapi full-stack template (SQLModel + 5-revision Alembic chain) - replayed migration schema equals the ORM columns exactly | P31: Django app label is taken from the directory (a custom AppConfig label would change table names); model references are resolved by simple name per repository and local variable types by assignment/annotation only; a model name used in two apps is reported ambiguous; Python is parsed with the server interpreter, so newer syntax (e.g. Python 3.14 'except A, B:') is a parse failure, reported as partial.
A32: T-031 | B32: R1 Platform foundation & cross-repo impact | C32: Extraction | D32: Java ORM + migration extraction: JPA entities, Spring Data repositories, Flyway SQL, Liquibase XML/YAML/JSON | E32: Entities (@Table/@Column/@JoinColumn/@JoinTable, Spring Boot naming strategy, @MappedSuperclass/@Embedded merge, @Transient), repository methods classified read/write by name and @Query/@Modifying/native queries (entities named by the query included), SQL DDL parser for PostgreSQL/MySQL/Oracle/SQL Server/HSQLDB statements, Liquibase createTable/addColumn/dropColumn/renameColumn/modifyDataType/not-null/dropTable/renameTable/sql; spring.datasource.url and tia-services.yaml database identity; EntityManager/JDBC/jOOQ/MyBatis, procedural SQL, stored procedure calls, custom naming strategy, @Inheritance and undeclared join tables reported as not analysed. | F32: FR-006a AC-023 | G32: tia/extract_java.py, tia/extract_data.py | H32: P0 | I32: Completed | J32: 1 | K32: M | N32: 46323 | O32: tests/test_data.py; run on real third-party code: spring-petclinic (6 entities, 20 repository accesses, 3 schema scripts, 0 unparsed), jhipster-sample-app (593 files: 5 entities, 7 Liquibase changelogs, 75 accesses, EntityManager/JDBC reported) - replayed Liquibase schema equals the JPA columns exactly; real-code runs found and fixed HSQLDB 'DROP TABLE x IF EXISTS', the org.springframework package-name filter and Django to= keyword / self-referential M2M | P32: Spring Data repositories are resolved only when they extend a Spring Data interface directly; default join-table names are not derived (reported); Liquibase files are found by 'changelog'/'liquibase' in the path; Flyway undo scripts ignored; XML with a DOCTYPE is refused (entity-expansion safety); several database flavours of one schema script in one repository are replayed together; Kotlin entities not supported.
A33: T-032 | B33: R1 Platform foundation & cross-repo impact | C33: Engine | D33: Data-impact traversal and findings (AC-024): schema change -> mapped entities -> reading/writing functions -> endpoints -> API consumers | E33: Data layer in the graph (entity, table, column, migration; MAPS_TO, MAPS_COLUMN, READS, WRITES, MIGRATES); tables belong to a database and services are linked only through a shared declared/URL-named database, never by table name; migration ops the head adds classified against the replayed schema (drop/rename table or column, type change vs provable widening, NOT NULL tightening, required new column = breaks writers only); findings per entity with accessors, own-repository rules (SEV-DATA-MAPPING-BROKEN / SEV-DATA-UPDATED), propagation through the existing call/endpoint/consumer traversal, unknowns for database identity, unanalysed data access, unparsed migration statements and unmapped changes; comment, redaction, graph view and impact overlay support the new node types. | F33: FR-015 AC-024 | G33: tia/data.py, tia/impact.py, tia/severity.py, tia/report.py, tia/graphview.py, tia/web/index.html | H33: P0 | I33: Completed | J33: 1 | K33: M | N33: 46323 | O33: tests/test_data.py (58); live: dev server on real PostgreSQL, real HTTP, queue + worker for 8 branches across Flyway/Liquibase/Alembic/Django, reproduce identical, real Chrome (findings table, impact overlay column -> 3 entities -> functions -> endpoints -> portal call sites, column search, 0 console errors) | P33: Column-level precision only for columns an analysed entity maps; type/nullability compatibility is not evaluated beyond provable widening; services using a database without a declared identity are assumed private (stated as an unknown); views, stored procedures and raw SQL are FR-041 (not built); same-repository functions reading a changed table are reported as direct low findings.
A34: T-033 | B34: R1 Platform foundation & cross-repo impact | C34: Platform | D34: Tenant lifecycle: provision, SCM installation mapping, suspend/resume, offboard with deletion certificate; per-tenant storage quota | E34: tenants admin class + CLI; suspended tenants get 403 tenant_suspended and their queued jobs are not claimed; offboarded 410; quota 403 storage_quota_exceeded; offboarding deletes every tenant table and returns a hashed certificate that verify_deletion re-checks. | F34: PL-013 AC-039 | G34: tia/tenants.py, tia/gate.py, tia/migrations/0007_tenant_lifecycle.sql | H34: P0 | I34: Completed | J34: 1 | K34: M | N34: 46323 | O34: tests/test_tenants.py (21); live: admin CLI + API + worker processes on PostgreSQL | P34: No billing/metering; SCM installation mapping is stored but a real GitHub App installation event is not wired (UC1-04).
A35: T-034 | B35: R1 Platform foundation & cross-repo impact | C35: Interfaces | D35: GitHub check run (always neutral) + POST publish endpoint for the PR comment; permalink in the comment | E35: check_run_payload (annotations <=50), upsert_check_run, publish_to_github, audit_publication; ScmConfig.check_run/public_url. | F35: FR-035 AC-020 | G35: tia/github.py, tia/publish.py, tia/api.py | H35: P0 | I35: Completed | J35: 1 | K35: M | N35: 46323 | O35: tests/test_publish.py (22) and tests/test_webhooks.py against a fake GitHub; comment upsert verified live on github.com earlier | P35: Check runs need a GitHub App token: simulated only, NOT verified against real GitHub.
A36: T-035 | B36: R1 Platform foundation & cross-repo impact | C36: Interfaces | D36: Permalink report page per analysis | E36: Server-rendered no-JS page GET /analyses/{id}: escaped, stacked cards under 700px, CSP + nosniff. | F36: PRD-9 | G36: tia/reportpage.py | H36: P0 | I36: Completed | J36: 1 | K36: M | N36: 46323 | O36: tests/test_reportpage.py (11) + real Chrome desktop and mobile widths
A37: T-036 | B37: R1 Platform foundation & cross-repo impact | C37: Security | D37: Secrets management and encryption: envelope encryption of tenant secrets, secret references, scrubbing, TLS enforcement | E37: KEK in a secrets manager (file/Vault Transit) -> per-tenant versioned DEK -> AES-256-GCM with tenant+name+version as AAD; refs file:/vault:/env:/NAME_FILE; scrub of token formats from graph, reports, logs, audit and job errors; refuses tokens over plaintext http, HSTS. | F37: PL-011 | G37: tia/credentials.py, tia/secretstore.py, tia/scrub.py, tia/transport.py | H37: P0 | I37: Completed | J37: 1 | K37: M | N37: 46323 | O37: tests/test_credentials.py (32), tests/test_secretstore.py (49); Vault only against a FAKE (KV v2 + Transit) | P37: NOT verified: real Vault, AWS KMS/Azure Key Vault wrappers (not built), customer-managed keys, PostgreSQL TLS handshake (embedded PG has no TLS).
A38: T-037 | B38: R1 Platform foundation & cross-repo impact | C38: Platform | D38: Platform observability: Prometheus metrics, JSON logs, W3C traces to OTLP, health/readiness | E38: Dependency-free metrics registry, request-id logs, traceparent through the queue into the worker, OTLP/HTTP JSON exporter, /healthz /readyz /metrics (token-protected), worker heartbeats and worker metrics port. | F38: PL-007 | G38: tia/metrics.py, tia/obs.py, tia/tracing.py, tia/health.py, tia/telemetry.py | H38: P0 | I38: Completed | J38: 1 | K38: M | N38: 46323 | O38: tests/test_observability.py (57); live API+worker processes; OTLP only against a fake collector | P38: NOT verified against a real Prometheus/OTel collector; no dashboards/alert rules shipped.
A39: T-038 | B39: R1 Platform foundation & cross-repo impact | C39: Engine | D39: Configuration management: versioned per-tenant limits, severity overrides, criticality, gateway prefixes, comment audience | E39: Strict validation (all problems at once), immutable insert-only versions, diff/restore, limits are defaults and ceilings, overrides recorded not silent, reproduce uses the snapshot's config; API + admin CLI + UI panel. | F39: PRD-7.3 | G39: tia/tenantconfig.py, tia/severity.py, tia/migrations/0010_tenant_config.sql | H39: P0 | I39: Completed | J39: 1 | K39: M | N39: 46323 | O39: tests/test_tenantconfig.py (65); live CLI -> API -> worker processes; real Chrome panel | P39: Only critical criticality changes severity; no approval workflow/RBAC (needs SSO UC1-18/19).
A40: T-039 | B40: R1 Platform foundation & cross-repo impact | C40: Security | D40: SSO: OIDC (authorization code + PKCE, bearer tokens) and SAML 2.0 (SP-initiated); service-account tokens; browser sessions | E40: Per-tenant identity providers; JWT verification limited to asymmetric algorithms with the key chosen by kid; provider fetches only to public https addresses; single-use sign-in state bound to the browser; SAML needs a signed assertion by a configured certificate (rotation supported), refuses XXE, signature wrapping, replay, unsolicited responses; service tokens carry roles and a repository scope, expire and are revocable, only their hash is stored; the credential names the tenant, so one deployment serves many tenants. | F40: PL-001 AC-025 | G40: tia/jwtverify.py, tia/netsafe.py, tia/identity.py, tia/oidc.py, tia/saml.py, tia/authapi.py, tia/migrations/0011_identity.sql | H40: P0 | I40: Completed | J40: 1 | K40: M | N40: 46323 | O40: tests/test_auth.py, tests/test_auth_api.py, tests/test_saml.py; live: admin CLI + API process + real Chrome through a real OIDC flow (4 people, sign-out, role change, CSRF, token shown once) | P40: Tested only against our own OIDC and SAML provider implementations: no real Entra/Okta/Keycloak/ADFS, so interoperability quirks (group-overage claim, signed AuthnRequests, encrypted assertions, single logout) are unverified; SHA-1 refusal in SAML not exercised; rate limiting left to a reverse proxy.
...

Sheet Next Tasks
A1: Next tasks to complete (ordered)
A2: Driven by 'Next order' on Task Tracker (1 = do first). Renumber there and this list updates.
A4: Order | B4: ID | C4: Task | D4: Release | E4: Requirement refs | F4: Effort | G4: Depends on | H4: Status | I4: Details / acceptance
A5: 1 | B5: =IFERROR(INDEX('Task Tracker'!$A$2:$A$251,MATCH($A5,'Task Tracker'!$M$2:$M$251,0)),"") -> T-051 | C5: =IFERROR(INDEX('Task Tracker'!$D$2:$D$251,MATCH($A5,'Task Tracker'!$M$2:$M$251,0)),"") -> PR comment + live verification via GitHub App | D5: =IFERROR(INDEX('Task Tracker'!$B$2:$B$251,MATCH($A5,'Task Tracker'!$M$2:$M$251,0)),"") -> R1 Platform foundation & cross-repo impact | E5: =IFERROR(INDEX('Task Tracker'!$F$2:$F$251,MATCH($A5,'Task Tracker'!$M$2:$M$251,0)),"") -> FR-035 AC-020 | F5: =IFERROR(INDEX('Task Tracker'!$K$2:$K$251,MATCH($A5,'Task Tracker'!$M$2:$M$251,0)),"") -> S | G5: =IFERROR(INDEX('Task Tracker'!$L$2:$L$251,MATCH($A5,'Task Tracker'!$M$2:$M$251,0)),"") -> GitHub App | H5: =IFERROR(INDEX('Task Tracker'!$I$2:$I$251,MATCH($A5,'Task Tracker'!$M$2:$M$251,0)),"") -> Not Started | I5: =IFERROR(INDEX('Task Tracker'!$E$2:$E$251,MATCH($A5,'Task Tracker'!$M$2:$M$251,0)),"") -> Update in place on push; never blocks merge.
A6: 2 | B6: =IFERROR(INDEX('Task Tracker'!$A$2:$A$251,MATCH($A6,'Task Tracker'!$M$2:$M$251,0)),"") -> T-052 | C6: =IFERROR(INDEX('Task Tracker'!$D$2:$D$251,MATCH($A6,'Task Tracker'!$M$2:$M$251,0)),"") -> Container images, Docker Compose, Helm chart | D6: =IFERROR(INDEX('Task Tracker'!$B$2:$B$251,MATCH($A6,'Task Tracker'!$M$2:$M$251,0)),"") -> R1 Platform foundation & cross-repo impact | E6: =IFERROR(INDEX('Task Tracker'!$F$2:$F$251,MATCH($A6,'Task Tracker'!$M$2:$M$251,0)),"") -> PL-009 | F6: =IFERROR(INDEX('Task Tracker'!$K$2:$K$251,MATCH($A6,'Task Tracker'!$M$2:$M$251,0)),"") -> M | G6: =IFERROR(INDEX('Task Tracker'!$L$2:$L$251,MATCH($A6,'Task Tracker'!$M$2:$M$251,0)),"") -> PostgreSQL, queue | H6: =IFERROR(INDEX('Task Tracker'!$I$2:$I$251,MATCH($A6,'Task Tracker'!$M$2:$M$251,0)),"") -> Not Started | I6: =IFERROR(INDEX('Task Tracker'!$E$2:$E$251,MATCH($A6,'Task Tracker'!$M$2:$M$251,0)),"") -> Images for SaaS and dedicated; documented data locations.
A7: 3 | B7: =IFERROR(INDEX('Task Tracker'!$A$2:$A$251,MATCH($A7,'Task Tracker'!$M$2:$M$251,0)),"") -> T-053 | C7: =IFERROR(INDEX('Task Tracker'!$D$2:$D$251,MATCH($A7,'Task Tracker'!$M$2:$M$251,0)),"") -> SaaS production environment (first region) | D7: =IFERROR(INDEX('Task Tracker'!$B$2:$B$251,MATCH($A7,'Task Tracker'!$M$2:$M$251,0)),"") -> R1 Platform foundation & cross-repo impact | E7: =IFERROR(INDEX('Task Tracker'!$F$2:$F$251,MATCH($A7,'Task Tracker'!$M$2:$M$251,0)),"") -> PL-009 PL-007 | F7: =IFERROR(INDEX('Task Tracker'!$K$2:$K$251,MATCH($A7,'Task Tracker'!$M$2:$M$251,0)),"") -> L | G7: =IFERROR(INDEX('Task Tracker'!$L$2:$L$251,MATCH($A7,'Task Tracker'!$M$2:$M$251,0)),"") -> Containers | H7: =IFERROR(INDEX('Task Tracker'!$I$2:$I$251,MATCH($A7,'Task Tracker'!$M$2:$M$251,0)),"") -> Not Started | I7: =IFERROR(INDEX('Task Tracker'!$E$2:$E$251,MATCH($A7,'Task Tracker'!$M$2:$M$251,0)),"") -> Infrastructure as code, gateway with tenant resolution and rate limits, managed PostgreSQL, evidence store, secrets, monitoring.
A8: 4 | B8: =IFERROR(INDEX('Task Tracker'!$A$2:$A$251,MATCH($A8,'Task Tracker'!$M$2:$M$251,0)),"") -> T-054 | C8: =IFERROR(INDEX('Task Tracker'!$D$2:$D$251,MATCH($A8,'Task Tracker'!$M$2:$M$251,0)),"") -> R1 release quality gate | D8: =IFERROR(INDEX('Task Tracker'!$B$2:$B$251,MATCH($A8,'Task Tracker'!$M$2:$M$251,0)),"") -> R1 Platform foundation & cross-repo impact | E8: =IFERROR(INDEX('Task Tracker'!$F$2:$F$251,MATCH($A8,'Task Tracker'!$M$2:$M$251,0)),"") -> PRD-19 | F8: =IFERROR(INDEX('Task Tracker'!$K$2:$K$251,MATCH($A8,'Task Tracker'!$M$2:$M$251,0)),"") -> S | G8: =IFERROR(INDEX('Task Tracker'!$L$2:$L$251,MATCH($A8,'Task Tracker'!$M$2:$M$251,0)),"") -> All R1 tasks | H8: =IFERROR(INDEX('Task Tracker'!$I$2:$I$251,MATCH($A8,'Task Tracker'!$M$2:$M$251,0)),"") -> Not Started | I8: =IFERROR(INDEX('Task Tracker'!$E$2:$E$251,MATCH($A8,'Task Tracker'!$M$2:$M$251,0)),"") -> All R1 ACs, accuracy, performance, security, operability, docs.
A9: 5 | B9: =IFERROR(INDEX('Task Tracker'!$A$2:$A$251,MATCH($A9,'Task Tracker'!$M$2:$M$251,0)),"") | C9: =IFERROR(INDEX('Task Tracker'!$D$2:$D$251,MATCH($A9,'Task Tracker'!$M$2:$M$251,0)),"") | D9: =IFERROR(INDEX('Task Tracker'!$B$2:$B$251,MATCH($A9,'Task Tracker'!$M$2:$M$251,0)),"") | E9: =IFERROR(INDEX('Task Tracker'!$F$2:$F$251,MATCH($A9,'Task Tracker'!$M$2:$M$251,0)),"") | F9: =IFERROR(INDEX('Task Tracker'!$K$2:$K$251,MATCH($A9,'Task Tracker'!$M$2:$M$251,0)),"") | G9: =IFERROR(INDEX('Task Tracker'!$L$2:$L$251,MATCH($A9,'Task Tracker'!$M$2:$M$251,0)),"") | H9: =IFERROR(INDEX('Task Tracker'!$I$2:$I$251,MATCH($A9,'Task Tracker'!$M$2:$M$251,0)),"") | I9: =IFERROR(INDEX('Task Tracker'!$E$2:$E$251,MATCH($A9,'Task Tracker'!$M$2:$M$251,0)),"")
A10: 6 | B10: =IFERROR(INDEX('Task Tracker'!$A$2:$A$251,MATCH($A10,'Task Tracker'!$M$2:$M$251,0)),"") | C10: =IFERROR(INDEX('Task Tracker'!$D$2:$D$251,MATCH($A10,'Task Tracker'!$M$2:$M$251,0)),"") | D10: =IFERROR(INDEX('Task Tracker'!$B$2:$B$251,MATCH($A10,'Task Tracker'!$M$2:$M$251,0)),"") | E10: =IFERROR(INDEX('Task Tracker'!$F$2:$F$251,MATCH($A10,'Task Tracker'!$M$2:$M$251,0)),"") | F10: =IFERROR(INDEX('Task Tracker'!$K$2:$K$251,MATCH($A10,'Task Tracker'!$M$2:$M$251,0)),"") | G10: =IFERROR(INDEX('Task Tracker'!$L$2:$L$251,MATCH($A10,'Task Tracker'!$M$2:$M$251,0)),"") | H10: =IFERROR(INDEX('Task Tracker'!$I$2:$I$251,MATCH($A10,'Task Tracker'!$M$2:$M$251,0)),"") | I10: =IFERROR(INDEX('Task Tracker'!$E$2:$E$251,MATCH($A10,'Task Tracker'!$M$2:$M$251,0)),"")
A11: 7 | B11: =IFERROR(INDEX('Task Tracker'!$A$2:$A$251,MATCH($A11,'Task Tracker'!$M$2:$M$251,0)),"") | C11: =IFERROR(INDEX('Task Tracker'!$D$2:$D$251,MATCH($A11,'Task Tracker'!$M$2:$M$251,0)),"") | D11: =IFERROR(INDEX('Task Tracker'!$B$2:$B$251,MATCH($A11,'Task Tracker'!$M$2:$M$251,0)),"") | E11: =IFERROR(INDEX('Task Tracker'!$F$2:$F$251,MATCH($A11,'Task Tracker'!$M$2:$M$251,0)),"") | F11: =IFERROR(INDEX('Task Tracker'!$K$2:$K$251,MATCH($A11,'Task Tracker'!$M$2:$M$251,0)),"") | G11: =IFERROR(INDEX('Task Tracker'!$L$2:$L$251,MATCH($A11,'Task Tracker'!$M$2:$M$251,0)),"") | H11: =IFERROR(INDEX('Task Tracker'!$I$2:$I$251,MATCH($A11,'Task Tracker'!$M$2:$M$251,0)),"") | I11: =IFERROR(INDEX('Task Tracker'!$E$2:$E$251,MATCH($A11,'Task Tracker'!$M$2:$M$251,0)),"")
A12: 8 | B12: =IFERROR(INDEX('Task Tracker'!$A$2:$A$251,MATCH($A12,'Task Tracker'!$M$2:$M$251,0)),"") | C12: =IFERROR(INDEX('Task Tracker'!$D$2:$D$251,MATCH($A12,'Task Tracker'!$M$2:$M$251,0)),"") | D12: =IFERROR(INDEX('Task Tracker'!$B$2:$B$251,MATCH($A12,'Task Tracker'!$M$2:$M$251,0)),"") | E12: =IFERROR(INDEX('Task Tracker'!$F$2:$F$251,MATCH($A12,'Task Tracker'!$M$2:$M$251,0)),"") | F12: =IFERROR(INDEX('Task Tracker'!$K$2:$K$251,MATCH($A12,'Task Tracker'!$M$2:$M$251,0)),"") | G12: =IFERROR(INDEX('Task Tracker'!$L$2:$L$251,MATCH($A12,'Task Tracker'!$M$2:$M$251,0)),"") | H12: =IFERROR(INDEX('Task Tracker'!$I$2:$I$251,MATCH($A12,'Task Tracker'!$M$2:$M$251,0)),"") | I12: =IFERROR(INDEX('Task Tracker'!$E$2:$E$251,MATCH($A12,'Task Tracker'!$M$2:$M$251,0)),"")
A13: 9 | B13: =IFERROR(INDEX('Task Tracker'!$A$2:$A$251,MATCH($A13,'Task Tracker'!$M$2:$M$251,0)),"") | C13: =IFERROR(INDEX('Task Tracker'!$D$2:$D$251,MATCH($A13,'Task Tracker'!$M$2:$M$251,0)),"") | D13: =IFERROR(INDEX('Task Tracker'!$B$2:$B$251,MATCH($A13,'Task Tracker'!$M$2:$M$251,0)),"") | E13: =IFERROR(INDEX('Task Tracker'!$F$2:$F$251,MATCH($A13,'Task Tracker'!$M$2:$M$251,0)),"") | F13: =IFERROR(INDEX('Task Tracker'!$K$2:$K$251,MATCH($A13,'Task Tracker'!$M$2:$M$251,0)),"") | G13: =IFERROR(INDEX('Task Tracker'!$L$2:$L$251,MATCH($A13,'Task Tracker'!$M$2:$M$251,0)),"") | H13: =IFERROR(INDEX('Task Tracker'!$I$2:$I$251,MATCH($A13,'Task Tracker'!$M$2:$M$251,0)),"") | I13: =IFERROR(INDEX('Task Tracker'!$E$2:$E$251,MATCH($A13,'Task Tracker'!$M$2:$M$251,0)),"")
A14: 10 | B14: =IFERROR(INDEX('Task Tracker'!$A$2:$A$251,MATCH($A14,'Task Tracker'!$M$2:$M$251,0)),"") | C14: =IFERROR(INDEX('Task Tracker'!$D$2:$D$251,MATCH($A14,'Task Tracker'!$M$2:$M$251,0)),"") | D14: =IFERROR(INDEX('Task Tracker'!$B$2:$B$251,MATCH($A14,'Task Tracker'!$M$2:$M$251,0)),"") | E14: =IFERROR(INDEX('Task Tracker'!$F$2:$F$251,MATCH($A14,'Task Tracker'!$M$2:$M$251,0)),"") | F14: =IFERROR(INDEX('Task Tracker'!$K$2:$K$251,MATCH($A14,'Task Tracker'!$M$2:$M$251,0)),"") | G14: =IFERROR(INDEX('Task Tracker'!$L$2:$L$251,MATCH($A14,'Task Tracker'!$M$2:$M$251,0)),"") | H14: =IFERROR(INDEX('Task Tracker'!$I$2:$I$251,MATCH($A14,'Task Tracker'!$M$2:$M$251,0)),"") | I14: =IFERROR(INDEX('Task Tracker'!$E$2:$E$251,MATCH($A14,'Task Tracker'!$M$2:$M$251,0)),"")
A15: 11 | B15: =IFERROR(INDEX('Task Tracker'!$A$2:$A$251,MATCH($A15,'Task Tracker'!$M$2:$M$251,0)),"") | C15: =IFERROR(INDEX('Task Tracker'!$D$2:$D$251,MATCH($A15,'Task Tracker'!$M$2:$M$251,0)),"") | D15: =IFERROR(INDEX('Task Tracker'!$B$2:$B$251,MATCH($A15,'Task Tracker'!$M$2:$M$251,0)),"") | E15: =IFERROR(INDEX('Task Tracker'!$F$2:$F$251,MATCH($A15,'Task Tracker'!$M$2:$M$251,0)),"") | F15: =IFERROR(INDEX('Task Tracker'!$K$2:$K$251,MATCH($A15,'Task Tracker'!$M$2:$M$251,0)),"") | G15: =IFERROR(INDEX('Task Tracker'!$L$2:$L$251,MATCH($A15,'Task Tracker'!$M$2:$M$251,0)),"") | H15: =IFERROR(INDEX('Task Tracker'!$I$2:$I$251,MATCH($A15,'Task Tracker'!$M$2:$M$251,0)),"") | I15: =IFERROR(INDEX('Task Tracker'!$E$2:$E$251,MATCH($A15,'Task Tracker'!$M$2:$M$251,0)),"")
A16: 12 | B16: =IFERROR(INDEX('Task Tracker'!$A$2:$A$251,MATCH($A16,'Task Tracker'!$M$2:$M$251,0)),"") | C16: =IFERROR(INDEX('Task Tracker'!$D$2:$D$251,MATCH($A16,'Task Tracker'!$M$2:$M$251,0)),"") | D16: =IFERROR(INDEX('Task Tracker'!$B$2:$B$251,MATCH($A16,'Task Tracker'!$M$2:$M$251,0)),"") | E16: =IFERROR(INDEX('Task Tracker'!$F$2:$F$251,MATCH($A16,'Task Tracker'!$M$2:$M$251,0)),"") | F16: =IFERROR(INDEX('Task Tracker'!$K$2:$K$251,MATCH($A16,'Task Tracker'!$M$2:$M$251,0)),"") | G16: =IFERROR(INDEX('Task Tracker'!$L$2:$L$251,MATCH($A16,'Task Tracker'!$M$2:$M$251,0)),"") | H16: =IFERROR(INDEX('Task Tracker'!$I$2:$I$251,MATCH($A16,'Task Tracker'!$M$2:$M$251,0)),"") | I16: =IFERROR(INDEX('Task Tracker'!$E$2:$E$251,MATCH($A16,'Task Tracker'!$M$2:$M$251,0)),"")
... A34: 30 | B34: =IFERROR(INDEX('Task Tracker'!$A$2:$A$251,MATCH($A34,'Task Tracker'!$M$2:$M$251,0)),"") | C34: =IFERROR(INDEX('Task Tracker'!$D$2:$D$251,MATCH($A34,'Task Tracker'!$M$2:$M$251,0)),"") | D34: =IFERROR(INDEX('Task Tracker'!$B$2:$B$251,MATCH($A34,'Task Tracker'!$M$2:$M$251,0)),"") | E34: =IFERROR(INDEX('Task Tracker'!$F$2:$F$251,MATCH($A34,'Task Tracker'!$M$2:$M$251,0)),"") | F34: =IFERROR(INDEX('Task Tracker'!$K$2:$K$251,MATCH($A34,'Task Tracker'!$M$2:$M$251,0)),"") | G34: =IFERROR(INDEX('Task Tracker'!$L$2:$L$251,MATCH($A34,'Task Tracker'!$M$2:$M$251,0)),"") | H34: =IFERROR(INDEX('Task Tracker'!$I$2:$I$251,MATCH($A34,'Task Tracker'!$M$2:$M$251,0)),"") | I34: =IFERROR(INDEX('Task Tracker'!$E$2:$E$251,MATCH($A34,'Task Tracker'!$M$2:$M$251,0)),"")

Sheet Requirements
A1: Req ID | B1: Requirement | C1: Release | D1: Status | E1: Gap / notes | F1: Tasks (IDs)
A2: FR-001 | B2: Repository connection | C2: R1 | D2: Partial | E2: GitHub (App and PAT), Azure DevOps (PAT), git URL, local and upload ingestion done; GitHub App verified against a stand-in only; Azure DevOps webhooks/App-equivalent not built | F2: T-017, T-018, T-028, T-041
A3: FR-002 | B3: Revision-aware analysis | C3: R1 | D3: Done | F3: T-008
A4: FR-003 | B4: Incremental analysis | C4: R1 | D4: Done | E4: Per-file incremental extraction + persisted versioned graph + full-rescan path with drift repair (Python) | F4: T-025
A5: FR-004 | B5: Supported languages (Java + Python) | C5: R1 | D5: Partial | E5: Java (Spring REST, JPA, Flyway/Liquibase) and Python (FastAPI/Flask, SQLAlchemy/Django ORM, Alembic/Django migrations) done; Django REST routes not extracted | F5: T-009, T-029
A6: FR-005 | B6: Repository freshness | C6: R1 | D6: Done | E6: Scan status, last successful scan, analysed revision, extractor version (snapshot), failures, stale relationships, inaccessible repos | F6: T-026
A7: FR-006 | B7: Core graph entities | C7: R1 | D7: Partial | E7: Service, endpoint, schema, function, call site, test, entity, table, column, migration done; deployment/build/event entities not built | F7: T-030
A8: FR-006a | B8: Data-access scope (ORM/migrations) | C8: R1 | D8: Done | E8: ORM mappings and migrations extracted; raw SQL/stored procedures (FR-041, R4) reported as data access not fully analysed | F8: T-030, T-031
A9: FR-007 | B9: Execution and operations entities | C9: R2 | D9: Not started | F9: T-059
A10: FR-008 | B10: Explicit relationship types | C10: R1 | D10: Done | F10: T-007
A11: FR-009 | B11: Relationship provenance | C11: R1 | D11: Partial | E11: No last-seen/validity yet (needs persisted graph)
A12: FR-010 | B12: Evidence classifications | C12: R1 | D12: Partial | E12: stale now produced; runtime_observed (R6) never produced yet | F12: T-007, T-026
A13: FR-011 | B13: Temporal relationships | C13: R3 | D13: Not started | F13: T-077
A14: FR-012 | B14: Changed-symbol identification | C14: R1 | D14: Done | E14: Python | F14: T-009, T-029
A15: FR-013 | B15: Dependency traversal | C15: R1 | D15: Done | F15: T-011, T-014, T-021
A16: FR-014 | B16: Cross-repository resolution | C16: R1 | D16: Partial | E16: R1-R5 done; R6 runtime in R2 | F16: T-010, T-060
A17: FR-015 | B17: Impact scope categories | C17: R1 | D17: Partial | E17: Code, contract, test and data impact done; runtime/operational categories not built | F17: T-014, T-032
A18: FR-016 | B18: Bounded traversal | C18: R1 | D18: Done | F18: T-014
A19: FR-017 | B19: API discovery | C19: R1 | D19: Partial | E19: FastAPI/Flask and Spring Web; endpoint authentication configuration not extracted | F19: T-009, T-029
A20: FR-018 | B20: API contract comparison | C20: R1/R2 | D20: Partial | E20: Basic P0 list done; full comparison R2 | F20: T-012, T-058
A21: FR-019 | B21: Event and message contracts | C21: R2 | D21: Not started | F21: T-059
A22: FR-020 | B22: Consumer impact report | C22: R1/R2 | D22: Partial | E22: REST done; events R2 | F22: T-059
A23: FR-021 | B23: Static test association | C23: R1 | D23: Done | E23: Python | F23: T-011
A24: FR-022 | B24: CI test results | C24: R2 | D24: Not started | F24: T-055
A25: FR-023 | B25: Coverage enrichment | C25: R2 | D25: Not started | F25: T-056
A26: FR-024 | B26: Regression recommendations | C26: R2 | D26: Not started | F26: T-057
A27: FR-025 | B27: Missing-test evidence | C27: R2 | D27: Partial | E27: Per-finding 'no relevant test evidence' limitation exists | F27: T-057
A28: FR-026 | B28: Runtime integration | C28: R2 | D28: Not started | F28: T-060
A29: FR-027 | B29: Runtime relationship classification | C29: R2 | D29: Not started | F29: T-060
A30: FR-028 | B30: Deployment correlation | C30: R2 | D30: Not started | F30: T-061
A31: FR-029 | B31: Environment-specific impact | C31: R2 | D31: Not started | F31: T-061
A32: FR-030 | B32: Change history | C32: R3 | D32: Not started | F32: T-077
A33: FR-031 | B33: Incident association | C33: R3 | D33: Not started | F33: T-078
A34: FR-032 | B34: Historical investigation | C34: R3 | D34: Not started | F34: T-079
A35: FR-033 | B35: Configurable policy rules | C35: R2 | D35: Not started | F35: T-062, T-063
A36: FR-034 | B36: Policy evaluation | C36: R2 | D36: Not started | F36: T-063
A37: FR-035 | B37: GitHub PR integration (comment + check) | C37: R1/R2 | D37: Partial | E37: Comment upsert live-verified; publish endpoint and check run built, check run simulated only (needs GitHub App) | F37: T-015, T-034, T-047, T-051, T-065
A38: FR-036 | B38: Advisory and enforcement modes | C38: R2 | D38: Not started | F38: T-064
A39: FR-037 | B39: Assistant / MCP distribution | C39: R2 | D39: Not started | F39: T-067
A40: FR-038 | B40: Change-management integration | C40: R2 | D40: Not started | F40: T-066
...

Sheet Acceptance Criteria
A1: AC | B1: Criterion (short) | C1: Release | D1: Status | E1: Notes | F1: Tasks (IDs)
A2: AC-001 | B2: Exact revisions | C2: 1 | D2: Done
A3: AC-002 | B3: Direct impact | C3: 1 | D3: Done
A4: AC-003 | B4: Transitive impact | C4: 1 | D4: Done
A5: AC-004 | B5: Contract impact | C5: 1 | D5: Done
A6: AC-005 | B6: Unresolved consumer | C6: 1 | D6: Done
A7: AC-006 | B7: Test association | C7: 1 | D7: Done
A8: AC-007 | B8: Runtime distinction | C8: 2 | D8: Not started | F8: T-060
A9: AC-008 | B9: No false coverage claim | C9: 2 | D9: Not started | F9: T-060
A10: AC-009 | B10: Failed scan | C10: 1 | D10: Done
A11: AC-010 | B11: Zero-impact result | C11: 1 | D11: Done
A12: AC-011 | B12: Stale relationships | C12: 1 | D12: Done | F12: T-026
A13: AC-012 | B13: Bounded traversal | C13: 1 | D13: Done
A14: AC-013 | B14: Policy failure | C14: 2 | D14: Not started | F14: T-063
A15: AC-014 | B15: Policy not evaluated | C15: 2 | D15: Not started | F15: T-063
A16: AC-015 | B16: Reproducible evidence | C16: 1 | D16: Done | E16: Snapshots materialised, pinned and reproduced identically (incl. after the landscape moved on) | F16: T-027
A17: AC-016 | B17: Access control | C17: 1 | D17: Done | E17: Per-reader redaction and 404 for unreadable repositories; GitHub mirror verified against a fake API, PR comment follows the readers rule | F17: T-040
A18: AC-017 | B18: No invented entities | C18: 1 | D18: Done
A19: AC-018 | B19: Resolution transparency | C19: 1 | D19: Done
A20: AC-019 | B20: Inference labelling | C20: 1 | D20: Done
A21: AC-020 | B21: PR comment | C21: 1 | D21: Partial | E21: Comment upsert live on github.com; check run simulated only | F21: T-034, T-051
A22: AC-021 | B22: Incremental update | C22: 1 | D22: Done | F22: T-025
A23: AC-022 | B23: Freshness | C23: 1 | D23: Done | F23: T-026
A24: AC-023 | B24: Java analysis | C24: 1 | D24: Done | F24: T-029, T-031
A25: AC-024 | B25: Data impact | C25: 1 | D25: Done | F25: T-032
A26: AC-025 | B26: SSO and RBAC | C26: 1 | D26: Done | E26: Roles enforced by a deny-by-default route table; tenant configuration (the policy stand-in) needs release_manager or administrator; every action audited with its actor; real IdP not used | F26: T-039, T-040
A27: AC-026 | B27: GitHub App | C27: 1 | D27: Done | E27: GitHub App JWT/installation tokens/routing/linking built and verified against a stand-in; no real GitHub App registered | F27: T-041
A28: AC-027 | B28: CI evidence | C28: 2 | D28: Not started | F28: T-055, T-056
A29: AC-028 | B29: Event impact | C29: 2 | D29: Not started | F29: T-059
A30: AC-029 | B30: Deployed version | C30: 2 | D30: Not started | F30: T-061
A31: AC-030 | B31: Enforcement mode | C31: 2 | D31: Not started | F31: T-064
A32: AC-031 | B32: ITSM | C32: 2 | D32: Not started | F32: T-066
A33: AC-032 | B33: MCP | C33: 2 | D33: Not started | F33: T-067
A34: AC-033 | B34: Temporal query | C34: 3 | D34: Not started | F34: T-077
A35: AC-034 | B35: Incident | C35: 3 | D35: Not started | F35: T-078, T-079
A36: AC-035 | B36: Tenant isolation | C36: 1 | D36: Partial | E36: Verified at storage layer (RLS tests) and at the API: the credential names the tenant, other tenants' reports, jobs and repositories answer 404 | F36: T-022
A37: AC-036 | B37: Additional SCM | C37: 4 | D37: Not started | F37: T-087
A38: AC-037 | B38: SQL lineage | C38: 4 | D38: Not started | F38: T-095
A39: AC-038 | B39: Calibration | C39: 4 | D39: Not started | F39: T-098
A40: AC-039 | B40: Tenant lifecycle | C40: 1 | D40: Done | F40: T-033
...

Sheet Use Cases
A1: Use case | B1: PRD ref | C1: State | D1: What works today | E1: What is missing | F1: Release | G1: Tasks (IDs)
A2: PR impact analysis | B2: 5.1 FR-035 | C2: Partial | D2: Branch/PR analysis from GitHub, Azure DevOps, git URL, local path; findings, severity, unknowns, PR-comment markdown; impact graph | E2: Automatic trigger on PR events (webhook), posting the comment back, check run, Java, ORM/data impact | F2: R1/R2 | G2: T-015, T-017, T-018, T-028, T-034, T-041, T-047, T-051, T-065
A3: API contract change | B3: 5.2 FR-018 FR-019 FR-020 | C3: Partial | D3: REST: removed/changed endpoint, removed/retyped response field, new required request field; consumers resolved via R1/R2/R3/R5 | E3: Events and message schemas, full compatibility rules, OpenAPI ingestion, consumer-specific CI test evidence | F3: R1/R2 | G3: T-012, T-058, T-059
A4: Explore the landscape (code graph) | B4: 9.2 | C4: Partial | D4: Service / endpoint / function graph with evidence colouring, search, focus, impact overlay | E4: Filters by severity/evidence/environment, saved views, large-landscape clustering, accessibility, persisted graph store | F4: R1/R2 | G4: T-020, T-021, T-068
A5: Production incident investigation | B5: 5.3 FR-031 FR-032 | C5: Not started | D5: - | E5: Incident ingestion, deployment and runtime evidence, historical graph, association labels (never root cause) | F5: R3 | G5: T-077, T-078, T-079
A6: Release-readiness assessment | B6: 5.4 FR-033 FR-034 FR-036 | C6: Not started | D6: - | E6: CI results, coverage, deployed versions, policy engine, advisory/enforcement mode, ITSM attachment | F6: R2 | G6: T-055, T-062, T-063, T-064, T-066
A7: Assistant / MCP retrieval | B7: FR-037 | C7: Not started | D7: REST API returns reports as JSON | E7: MCP server, read-only tools | F7: R2 | G7: T-067
A8: Governance and audit reporting | B8: 11.3 11.4 | C8: Not started | D8: JSONL audit of analyses | E8: Tamper-evident audit, retention enforcement, audit reports, RBAC | F8: R1/R3 | G8: T-015, T-023, T-040, T-048, T-080

Sheet UC1 Definition of Done
A1: Use case 1 - Pull-request impact analysis (PRD 5.1): definition of done
A2: The use case is CLOSED only when every row is 'Verified (live)', or the user explicitly waives live verification for a row. Levels: Not started < In progress < Built < Verified (simulated: tests/fakes) < Verified (live: real GitHub / Azure DevOps / IdP). Rows marked LIVE-NEEDED cannot reach 'Verified (live)' without your credentials/accounts.
A3: Progress | B3: =COUNTIF(F5:F34,"Verified (live)")&" live-verified, "&COUNTIF(F5:F34,"Verified (simulated)")&" simulated, "&COUNTIF(F5:F34,"Built")&" built, "&COUNTIF(F5:F34,"In progress")&" in progress, "&COUNTIF(F5:F34,"Not started")&" not started, of "&COUNTA(A5:A34) -> 16 live-verified, 11 simulated, 0 built, 0 in progress, 3 not started, of 30 | G3: Use case closed? | H3: =IF(COUNTIF(F5:F34,"Verified (live)")=COUNTA(A5:A34),"CLOSED","OPEN") -> OPEN
A4: ID | B4: PRD 5.1 step | C4: Item (must all be true) | D4: Requirement refs | E4: Needs live external account | F4: Status | G4: Verified by | H4: Notes
A5: UC1-01 | B5: all | C5: Multi-tenant PostgreSQL storage: schema, migrations, forced RLS, non-owner app role, tenant context per transaction | D5: PL-003 AC-035 TFD-9 | F5: Verified (live) | G5: tests/test_storage.py + app running on PostgreSQL | H5: Real PostgreSQL 16.2 (embedded). Managed-PG/PgBouncer deployment not tested
A6: UC1-02 | B6: all | C6: Tamper-evident (hash-chained, append-only) audit trail incl. external writes | D6: 11.3 | F6: Verified (live) | G6: tests/test_storage.py + tests/test_auth_api.py (actor on every action, denials, logins); live: audit chain verified after sign-ins, token and role changes | H6: Azure DevOps comment writes will be audited when UC1-15 is built
A7: UC1-03 | B7: 1 | C7: Job queue on PostgreSQL: idempotent submission, retries, per-tenant fair scheduling, newest-revision-wins supersede | D7: PL-017 AC-040 TFD-8/12 | F7: Verified (live) | G7: tests/test_jobs.py (20) + live dev server | H7: Real PostgreSQL 16.2; webhook-triggered enqueue is UC1-05/06
A8: UC1-04 | B8: 1,2 | C8: GitHub App connector: App JWT + installation tokens, repo registration, clone/fetch with installation token, permission-failure reporting | D8: FR-001 AC-026 | E8: LIVE-NEEDED | F8: Verified (simulated) | G8: tests/test_githubapp.py (51); live: CLI + API + worker processes against a GitHub platform stand-in | H8: No real GitHub App registered; GitHub's real permission model and the user-authorisation redirect untested
A9: UC1-05 | B9: 1 | C9: GitHub webhook receiver: HMAC signature verification, delivery-id idempotency, opened/synchronize/reopened/closed handling | D9: FR-001 AC-026 | E9: LIVE-NEEDED | F9: Verified (simulated) | G9: tests/test_webhooks.py: signature, parsing, guards, delivery dedupe, supersede, e2e; a locally signed delivery of the real sandbox PR updated its real GitHub comment | H9: Delivery FROM github.com via a tunnel not done (cloudflared download blocked); closed/merged handling is a no-op; tenant from deployment until SSO
A10: UC1-06 | B10: 1,2 | C10: Azure DevOps: service-hook receiver (PR created/updated) with auth verification, PR fetch, repo registration | D10: FR-001 FR-039 | E10: LIVE-NEEDED | F10: Not started | H10: Ingestion by PAT already works (simulated)
A11: UC1-07 | B11: 3,4 | C11: Java / Spring adapter: routes, RestTemplate/WebClient/Feign, generated clients, tests | D11: FR-004 FR-017 AC-023 | F11: Verified (live) | G11: tests/test_java.py (35) + real spring-petclinic-microservices code (54 files, 0 parse failures) | H11: REST side only: AC-023 also needs JPA data access (UC1-08); see task notes for framework limits
A12: UC1-08 | B12: 4 | C12: Python ORM and migration extraction (SQLAlchemy, Django ORM, Alembic, Django migrations) | D12: FR-006 FR-006a | F12: Verified (live) | G12: tests/test_data.py + real django-realworld-example-app and fastapi full-stack template (schema replayed from migrations equals ORM columns exactly) | H12: Raw SQL, Table() objects, dynamic table names, RunPython reported as unknown; see task notes
A13: UC1-09 | B13: 4 | C13: Java ORM and migration extraction (JPA, Spring Data, Flyway/Liquibase) | D13: FR-006a AC-023 | F13: Verified (live) | G13: tests/test_data.py + real spring-petclinic and jhipster-sample-app (Liquibase replay equals JPA columns exactly) | H13: EntityManager/JDBC/jOOQ, procedural SQL, custom naming strategy, undeclared join tables reported as unknown; see task notes
A14: UC1-10 | B14: 4 | C14: Data-impact traversal and findings (migration/schema change -> services via ORM mappings) | D14: FR-015 AC-024 | F14: Verified (live) | G14: tests/test_data.py + live dev server on PostgreSQL (HTTP, queue+worker, 8 branches, reproduce identical) + real Chrome (impact overlay, search, 0 console errors) | H14: Shared-database identity must be declared or come from a literal JDBC URL; column precision only for mapped columns; FR-041 (SQL lineage) not built
A15: UC1-11 | B15: 3,4 | C15: Persisted versioned graph with incremental invalidation; full-rescan path; graph equals full rescan | D15: FR-003 AC-021 | F15: Verified (live) | G15: tests/test_incremental.py + tests/test_graph_versions.py; also run live against the GitHub sandbox repos | H15: Real PostgreSQL 16.2 + real git. Python adapter only; Java is UC1-07
A16: UC1-12 | B16: 6 | C16: Stale-relationship handling and repository freshness tracking | D16: FR-005 FR-010 AC-011 AC-022 | F16: Verified (live) | G16: tests/test_stale.py (6) incl. a real failed fetch and recovery | H16: Real PostgreSQL + real git remotes (file URLs). A GitHub-side outage was not induced
A17: UC1-13 | B17: 6 | C17: Evidence snapshots materialised; re-analysis on a snapshot is identical | D17: AC-015 | F17: Verified (live) | G17: tests/test_snapshots.py (8); reproduced on the GitHub sandbox PR | H17: Local repositories cannot be pinned
